<?xml version="1.0"?>
<robot xmlns:xacro="http://www.ros.org/wiki/xacro" name="robot">

    <xacro:include filename="inertial_macros.xacro"/>

    <!-- chasis color -->

    <material name="white">
        <color rgba="1 1 1 1" />
    </material>

    <material name="red">
        <color rgba="1 0 0 1"/>
    </material>

    <material name="blue">
        <color rgba="0.2 0.2 1 1"/>
    </material>

    <material name="black"> 
        <color rgba="0 0 0 1"/>
    </material>

    <material name="gray">
        <color rgba="0.7 0.7 0.7 1"/>
    </material>

    <!-- BASE LINK -->

    <link name="base_link">

    </link>

    <!-- Base foot print link for slam application-->
    <joint name="base_footprint_joint" type="fixed">
        <parent link="base_link"/>
        <child link="base_footprint"/>
        <origin xyz="0 0 0"/>
    </joint>

    <link name="base_footprint">

    </link>


    <!-- CHASSIS LINK -->

    <joint name="chassis_joint" type="fixed">
        <parent link="base_link"/>
        <child link="chassis"/>
        <origin xyz="0 0 0."/>
    </joint>

    <link name="chassis">
        <visual>
            <origin xyz="0 0 0"/>
            <geometry>
                <box size="0.8 0.4 0.15"/>
            </geometry>
            <material name="white"/>
        </visual>
        <collision>
            <origin xyz="0.0 0 0.0"/>
            <geometry>
                <box size="0.8 0.4 0.15"/>
            </geometry>
        </collision>
        <xacro:inertial_box mass="0.5" x="0.8" y="0.4" z="0.15">
            <origin xyz="0.0 0 0.0" rpy="0 0 0"/>
        </xacro:inertial_box>
    </link>
    
    <gazebo reference="chassis">
        <material>Gazebo/White</material>
    </gazebo>


    <!-- Smaller Box -->
    <link name="smaller_box">
        <visual>
            <origin xyz="0 0 0" rpy="0 0 0"/>
            <geometry>
                <box size="0.15 0.2 0.1"/>
            </geometry>
            <material name="gray"/>
        </visual>
        <collision>
            <origin xyz="0.0 0 0.0"/>
            <geometry>
                <box size="0.1 0.2 0.1"/>
            </geometry>
        </collision>
        <xacro:inertial_box mass="0.2" x="0.1" y="0.2" z="0.1">
            <origin xyz="0.0 0 0.0" rpy="0 0 0"/>
        </xacro:inertial_box>
    </link>

    <!-- Joints -->
    <joint name="smaller_box_to_base_joint" type="fixed">
        <parent link="chassis"/>
        <child link="smaller_box"/>
        <origin xyz="0 0 0.075"/>
    </joint>

    <gazebo reference="smaller_box">
        <material>Gazebo/Gray</material>
    </gazebo>




    <!--  Front LEFT WHEEL LINK -->

    <joint name="front_left_wheel_joint" type="continuous">
        <parent link="base_link"/>
        <child link="front_left_wheel"/>
        <origin xyz="0.2 0.24 0" rpy="-1.5714 0 0" />
        <axis xyz="0 0 1"/>
    </joint>

    <link name="front_left_wheel">
        <visual>
            <geometry>
                <cylinder radius="0.1" length="0.08"/>
            </geometry>
            <material name="blue"/>
        </visual>
        <collision>
            <geometry>
                <cylinder radius="0.1" length="0.08"/>
            </geometry>
        </collision>
        <xacro:inertial_cylinder mass="0.1" length="0.08" radius="0.1">
            <origin xyz="0 0 0" rpy="0 0 0"/>
        </xacro:inertial_cylinder>
    </link>

    <gazebo reference="front_left_wheel">
        <material>Gazebo/Blue</material>
    </gazebo>




    <!-- Front_RIGHT WHEEL LINK -->
    <joint name="front_right_wheel_joint" type="continuous">
        <parent link="base_link"/>
        <child link="front_right_wheel"/>
        <origin xyz="0.2 -0.24 0" rpy="1.5714 0 0" />  <!-- pi/2 = 1.5714 -->
        <axis xyz="0 0 -1"/>
    </joint>
    <link name="front_right_wheel">
        <visual>
            <geometry>
                <cylinder radius="0.1" length="0.08"/>
            </geometry>
            <material name="blue"/>
        </visual>
        <collision>
            <geometry>
                <cylinder radius="0.1" length="0.08"/>
            </geometry>
        </collision>
        <xacro:inertial_cylinder mass="0.1" length="0.08" radius="0.1">
            <origin xyz="0 0 0" rpy="0 0 0"/>
        </xacro:inertial_cylinder>
    </link>
    <gazebo reference="front_right_wheel">
        <material>Gazebo/Blue</material>
    </gazebo>

    <!--  Rear LEFT WHEEL LINK -->
    <joint name="rear_left_wheel_joint" type="continuous">
        <parent link="base_link"/>
        <child link="rear_left_wheel"/>
        <origin xyz="-0.2 0.24 0" rpy="-1.5714 0 0" />
        <axis xyz="0 0 1"/>
    </joint>
    <link name="rear_left_wheel">
        <visual>
            <geometry>
                <cylinder radius="0.1" length="0.08"/>
            </geometry>
            <material name="blue"/>
        </visual>
        <collision>
            <geometry>
                <cylinder radius="0.1" length="0.08"/>
            </geometry>
        </collision>
        <xacro:inertial_cylinder mass="0.1" length="0.08" radius="0.1">
            <origin xyz="0 0 0" rpy="0 0 0"/>
        </xacro:inertial_cylinder>
    </link>    
    <gazebo reference="rear_left_wheel">
        <material>Gazebo/Blue</material>
    </gazebo>


    <!--  Rear right WHEEL LINK -->
    <joint name="rear_right_wheel_joint" type="continuous">
        <parent link="base_link"/>
        <child link="rear_right_wheel"/>
        <origin xyz="-0.2 -0.24 0" rpy="1.5714 0 0" />
        <axis xyz="0 0 -1"/>
    </joint>
    <link name="rear_right_wheel">
        <visual>
            <geometry>
                <cylinder radius="0.1" length="0.08"/>
            </geometry>
            <material name="blue"/>
        </visual>
        <collision>
            <geometry>
                <cylinder radius="0.1" length="0.08"/>
            </geometry>
        </collision>
        <xacro:inertial_cylinder mass="0.1" length="0.08" radius="0.1">
            <origin xyz="0 0 0" rpy="0 0 0"/>
        </xacro:inertial_cylinder>
    </link>
    <gazebo reference="rear_right_wheel">
        <material>Gazebo/Blue</material>
    </gazebo>
</robot>